<?xml version="1.0" ?>
<!-- =================================================================================== -->
<!-- |    This document was autogenerated by xacro from martlet9.urdf.xacro            | -->
<!-- |    EDITING THIS FILE BY HAND IS NOT RECOMMENDED                                 | -->
<!-- =================================================================================== -->
<robot name="martlet9" xmlns:xacro="http://www.ros.org/wiki/xacro">
  <material name="white">
    <color rgba="1 1 1 1"/>
  </material>
  <material name="darkgrey">
    <color rgba="0.1 0.1 0.1 1"/>
  </material>
  <material name="grey">
    <color rgba="0.4 0.4 0.4 0.9"/>
  </material>
  <material name="thruster_fire_mat">
    <color rgba="1.0 1.0 0.3 0.0"/>
  </material>
  <material name="steering_smoke_mat">
    <color rgba="0.3 0.3 0.3 0.0"/>
  </material>
  <link name="base">
    <visual>
      <geometry>
        <cylinder length="70" radius="1.85"/>
      </geometry>
      <material name="white"/>
    </visual>
    <collision>
      <geometry>
        <cylinder length="70" radius="1.85"/>
      </geometry>
    </collision>
    <inertial>
      <mass value="400000"/>
      <inertia ixx="163675583.3333333" ixy="0" ixz="0" iyy="163675583.3333333" iyz="0" izz="684500.0"/>
    </inertial>
  </link>
  <link name="thruster_casing">
    <visual>
      <geometry>
        <cylinder length="8" radius="1.7"/>
      </geometry>
      <material name="grey"/>
    </visual>
    <collision>
      <geometry>
        <cylinder length="" radius="1.7"/>
      </geometry>
    </collision>
    <inertial>
      <mass value="100000"/>
      <inertia ixx="" ixy="0" ixz="0" iyy="605583.3333333334" iyz="0" izz="144500.0"/>
    </inertial>
  </link>
  <link name="thruster">
    <visual>
      <geometry>
        <cylinder length="4" radius="1.2"/>
      </geometry>
      <material name="darkgrey"/>
    </visual>
    <collision>
      <geometry>
        <cylinder length="4" radius="1.2"/>
      </geometry>
    </collision>
    <inertial>
      <mass value="75000"/>
      <inertia ixx="127000.0" ixy="0" ixz="0" iyy="127000.0" iyz="0" izz="54000.0"/>
    </inertial>
  </link>
  <link name="thruster_fire">
    <visual>
      <geometry>
        <cylinder length="5" radius="1.08"/>
      </geometry>
      <material name="thruster_fire_mat"/>
    </visual>
    <inertial>
      <mass value="0"/>
      <inertia ixx="1" ixy="0" ixz="0" iyy="1" iyz="0" izz="1"/>
    </inertial>
  </link>
  <link name="steer1_wheel">
    <visual>
      <geometry>
        <cylinder length="0.5" radius="2.035"/>
      </geometry>
      <material name="grey"/>
    </visual>
    <collision>
      <geometry>
        <cylinder length="0.5" radius="2.035"/>
      </geometry>
    </collision>
    <inertial>
      <mass value="100"/>
      <inertia ixx="1" ixy="0" ixz="0" iyy="1" iyz="0" izz="1"/>
    </inertial>
  </link>
  <link name="steer1_gun">
    <visual>
      <geometry>
        <box size="1 0.25 0.25"/>
      </geometry>
      <material name="darkgrey"/>
    </visual>
    <collision>
      <geometry>
        <box size="1 0.25 0.25"/>
      </geometry>
    </collision>
    <inertial>
      <mass value="75"/>
      <inertia ixx="1" ixy="0" ixz="0" iyy="1" iyz="0" izz="1"/>
    </inertial>
  </link>
  <link name="steer1_smoke">
    <visual>
      <geometry>
        <cylinder length="5" radius="0.225"/>
      </geometry>
      <origin rpy="0 1.57 0"/>
      <material name="steering_smoke_mat"/>
    </visual>
    <inertial>
      <mass value="0"/>
      <inertia ixx="1" ixy="0" ixz="0" iyy="1" iyz="0" izz="1"/>
    </inertial>
  </link>
  <link name="leg1">
    <visual>
      <geometry>
        <box size="12 0.3 0.3"/>
      </geometry>
      <origin rpy="0 0.524 0"/>
      <material name="darkgrey"/>
    </visual>
    <collision>
      <geometry>
        <box size="12 0.3 0.3"/>
      </geometry>
      <origin rpy="0 0.524 0"/>
    </collision>
    <inertial>
      <mass value="1000"/>
      <inertia ixx="1" ixy="0" ixz="0" iyy="1" iyz="0" izz="1"/>
    </inertial>
  </link>
  <link name="leg2">
    <visual>
      <geometry>
        <box size="12 0.3 0.3"/>
      </geometry>
      <origin rpy="0 0.524 2.094"/>
      <material name="darkgrey"/>
    </visual>
    <collision>
      <geometry>
        <box size="12 0.3 0.3"/>
      </geometry>
      <origin rpy="0 0.524 2.094"/>
    </collision>
    <inertial>
      <mass value="1000"/>
      <inertia ixx="1" ixy="0" ixz="0" iyy="1" iyz="0" izz="1"/>
    </inertial>
  </link>
  <link name="leg3">
    <visual>
      <geometry>
        <box size="12 0.3 0.3"/>
      </geometry>
      <origin rpy="0 0.524 4.189"/>
      <material name="darkgrey"/>
    </visual>
    <collision>
      <geometry>
        <box size="12 0.3 0.3"/>
      </geometry>
      <origin rpy="0 0.524 4.189"/>
    </collision>
    <inertial>
      <mass value="1000"/>
      <inertia ixx="1" ixy="0" ixz="0" iyy="1" iyz="0" izz="1"/>
    </inertial>
  </link>
  <link name="ball1">
    <visual>
      <geometry>
        <sphere radius="1.0"/>
      </geometry>
      <material name="darkgrey"/>
    </visual>
    <collision>
      <geometry>
        <sphere radius="1.0"/>
      </geometry>
    </collision>
    <inertial>
      <mass value="10000"/>
      <inertia ixx="1" ixy="0" ixz="0" iyy="1" iyz="0" izz="1"/>
    </inertial>
  </link>
  <link name="ball2">
    <visual>
      <geometry>
        <sphere radius="1.0"/>
      </geometry>
      <material name="darkgrey"/>
    </visual>
    <collision>
      <geometry>
        <sphere radius="1.0"/>
      </geometry>
    </collision>
    <inertial>
      <mass value="10000"/>
      <inertia ixx="1" ixy="0" ixz="0" iyy="1" iyz="0" izz="1"/>
    </inertial>
  </link>
  <link name="ball3">
    <visual>
      <geometry>
        <sphere radius="1.0"/>
      </geometry>
      <material name="darkgrey"/>
    </visual>
    <collision>
      <geometry>
        <sphere radius="1.0"/>
      </geometry>
    </collision>
    <inertial>
      <mass value="10000"/>
      <inertia ixx="1" ixy="0" ixz="0" iyy="1" iyz="0" izz="1"/>
    </inertial>
  </link>
  <joint name="base_to_leg1" type="fixed">
    <parent link="base"/>
    <child link="leg1"/>
    <origin xyz="6.0 0 -34.5"/>
  </joint>
  <joint name="base_to_leg2" type="fixed">
    <parent link="base"/>
    <child link="leg2"/>
    <origin xyz="-3.0 5.20 -34.5"/>
  </joint>
  <joint name="base_to_leg3" type="fixed">
    <parent link="base"/>
    <child link="leg3"/>
    <origin xyz="-3.0 -5.20 -34.5"/>
  </joint>
  <joint name="base_to_thruster_casing" type="fixed">
    <parent link="base"/>
    <child link="thruster_casing"/>
    <origin xyz="0 0 -32"/>
  </joint>
  <joint name="thruster_casing_to_thruster" type="fixed">
    <parent link="thruster_casing"/>
    <child link="thruster"/>
    <origin xyz="0 0 -3"/>
  </joint>
  <joint name="thruster_to_fire" type="fixed">
    <parent link="thruster"/>
    <child link="thruster_fire"/>
    <origin xyz="0 0 -5.0"/>
  </joint>
  <joint name="base_to_steer1_wheel" type="continuous">
    <parent link="base"/>
    <child link="steer1_wheel"/>
    <origin xyz="0 0 20"/>
    <axis xyz="0 0 1"/>
  </joint>
  <joint name="steer1_wheel_to_steer1_gun" type="fixed">
    <parent link="steer1_wheel"/>
    <child link="steer1_gun"/>
    <origin xyz="2.535 0 0"/>
  </joint>
  <joint name="steer1_gun_to_smoke" type="fixed">
    <parent link="steer1_gun"/>
    <child link="steer1_smoke"/>
    <origin xyz="3.5 0 0"/>
  </joint>
  <joint name="leg1_to_ball" type="fixed">
    <parent link="leg1"/>
    <child link="ball1"/>
    <origin xyz="4.5 0 -3"/>
  </joint>
  <joint name="leg2_to_ball" type="fixed">
    <parent link="leg2"/>
    <child link="ball2"/>
    <origin xyz="-2.25 3.89 -3"/>
  </joint>
  <joint name="leg3_to_ball" type="fixed">
    <parent link="leg3"/>
    <child link="ball3"/>
    <origin xyz="-2.25 -3.89 -3"/>
  </joint>
</robot>

